<?xml version="1.0" encoding="utf-8"?>
<robot xmlns:xacro="http://www.ros.org/wiki/xacro" name="arm">
  <!-- 定义 mesh 文件目录 -->
  <xacro:property name="mesh_dir" value="package://mentorpi_description/meshes/arm" />

  <!-- link1 -->
  <link name="link1">
    <inertial>
      <origin xyz="-5.67434079306178E-05 -0.00183922864739318 0.0128899047255676" rpy="0 0 0"/>
      <mass value="0.0118309583811137"/>
      <inertia ixx="1.4948064066526E-06" ixy="-4.84499294246996E-09" ixz="-7.07755635870065E-09"
               iyy="1.83446645758585E-06" iyz="2.91602544513314E-08" izz="1.90385026531022E-06"/>
    </inertial>
    <visual>
      <origin xyz="0 0 0" rpy="0 0 0"/>
      <geometry>
        <mesh filename="${mesh_dir}/link1.STL"/>
      </geometry>
      <material name="">
        <color rgba="0.792156862745098 0.819607843137255 0.933333333333333 1"/>
      </material>
    </visual>
    <collision>
      <origin xyz="0 0 0" rpy="0 0 0"/>
      <geometry>
        <mesh filename="${mesh_dir}/link1.STL"/>
      </geometry>
    </collision>
  </link>

  <!-- joint1 -->
  <joint name="joint1" type="revolute">
    <origin xyz="0.0798305157765817 0.00796999989406598 -0.00881105926199899" rpy="0 0 0"/>
    <parent link="back_shell_black_link"/>
    <child link="link1"/>
    <axis xyz="0 -0.00872653549837298 0.999961923064171"/>
    <limit lower="-2.09" upper="2.09" effort="1000" velocity="10"/>
  </joint>

  <!-- link2 -->
  <link name="link2">
    <inertial>
      <origin xyz="-4.90949608693142E-05 -0.0172946567203177 0.0348468784939513" rpy="0 0 0"/>
      <mass value="0.0134442645715788"/>
      <inertia ixx="2.06831776804487E-06" ixy="-4.83298815351655E-09" ixz="-7.08265998322103E-09"
               iyy="1.86607200913389E-06" iyz="2.9217965782543E-08" izz="1.9164758927137E-06"/>
    </inertial>
    <visual>
      <origin xyz="0 0 0" rpy="0 0 0"/>
      <geometry>
        <mesh filename="${mesh_dir}/link2.STL"/>
      </geometry>
      <material name="">
        <color rgba="0.792156862745098 0.819607843137255 0.933333333333333 1"/>
      </material>
    </visual>
    <collision>
      <origin xyz="0 0 0" rpy="0 0 0"/>
      <geometry>
        <mesh filename="${mesh_dir}/link2.STL"/>
      </geometry>
    </collision>
  </link>

  <!-- joint2 -->
  <joint name="joint2" type="revolute">
    <origin xyz="0 0.0157173842856447 0.029407276270124" rpy="0 0 0"/>
    <parent link="link1"/>
    <child link="link2"/>
    <axis xyz="-0.000112352847229615 0.999999993633059 1.05223831512449E-05"/>
    <limit lower="-2.09" upper="2.09" effort="1000" velocity="10"/>
  </joint>

  <!-- link3 -->
  <link name="link3">
    <inertial>
      <origin xyz="-4.76813362449563E-05 -0.0137946721313249 0.0344376377868522" rpy="0 0 0"/>
      <mass value="0.0134442539370621"/>
      <inertia ixx="2.06831774027413E-06" ixy="-4.83209403973337E-09" ixz="-7.08842633910329E-09"
               iyy="1.86607177122307E-06" iyz="2.92181111168874E-08" izz="1.91647544902917E-06"/>
    </inertial>
    <visual>
      <origin xyz="0 0 0" rpy="0 0 0"/>
      <geometry>
        <mesh filename="${mesh_dir}/link3.STL"/>
      </geometry>
      <material name="">
        <color rgba="0.792156862745098 0.819607843137255 0.933333333333333 1"/>
      </material>
    </visual>
    <collision>
      <origin xyz="0 0 0" rpy="0 0 0"/>
      <geometry>
        <mesh filename="${mesh_dir}/link3.STL"/>
      </geometry>
    </collision>
  </link>

  <!-- joint3 -->
  <joint name="joint3" type="revolute">
    <origin xyz="0 -0.00349999581263584 0.058909248362693" rpy="0 0 0"/>
    <parent link="link2"/>
    <child link="link3"/>
    <axis xyz="-0.000112352437232682 0.999999993633058 1.05267588869922E-05"/>
    <limit lower="-2.09" upper="2.09" effort="1000" velocity="10"/>
  </joint>

  <!-- link4 -->
  <link name="link4">
    <inertial>
      <origin xyz="0.00143524645309828 -0.0167069974511767 0.0241990457924445" rpy="0 0 0"/>
      <mass value="0.00751568482683344"/>
      <inertia ixx="3.13134309946978E-06" ixy="3.87926635588682E-11" ixz="-9.93983625095093E-08"
               iyy="2.11375809341781E-06" iyz="1.06167346468313E-12" izz="2.56548837345213E-06"/>
    </inertial>
    <visual>
      <origin xyz="0 0 0" rpy="0 0 0"/>
      <geometry>
        <mesh filename="${mesh_dir}/link4.STL"/>
      </geometry>
      <material name="">
        <color rgba="0.792156862745098 0.819607843137255 0.933333333333333 1"/>
      </material>
    </visual>
    <collision>
      <origin xyz="0 0 0" rpy="0 0 0"/>
      <geometry>
        <mesh filename="${mesh_dir}/link4.STL"/>
      </geometry>
    </collision>
  </link>

  <!-- joint4 -->
  <joint name="joint4" type="revolute">
    <origin xyz="0 0.00421260365547117 0.058229966123689" rpy="0 0 0"/>
    <parent link="link3"/>
    <child link="link4"/>
    <axis xyz="0.000112346753801722 0.999999993633766 -1.05202298862951E-05"/>
    <limit lower="-2.09" upper="2.09" effort="1000" velocity="10"/>
  </joint>

  <!-- servo_link2 -->
  <link name="servo_link2">
    <inertial>
      <origin xyz="0.0160556477372382 0.000101325169773916 0.00233279411555282" rpy="0 0 0"/>
      <mass value="0.00675743001634433"/>
      <inertia ixx="5.1836712981768E-07" ixy="-7.07709484856157E-09" ixz="-2.92210658889632E-08"
               iyy="7.56467305262085E-07" iyz="4.84482611424056E-09" izz="1.14967550158165E-06"/>
    </inertial>
    <visual>
      <origin xyz="0 0 0" rpy="0 0 0"/>
      <geometry>
        <mesh filename="${mesh_dir}/servo_link2.STL"/>
      </geometry>
      <material name="">
        <color rgba="0.792156862745098 0.819607843137255 0.933333333333333 1"/>
      </material>
    </visual>
    <collision>
      <origin xyz="0 0 0" rpy="0 0 0"/>
      <geometry>
        <mesh filename="${mesh_dir}/servo_link2.STL"/>
      </geometry>
    </collision>
  </link>

  <!-- servo_joint2 -->
  <joint name="servo_joint2" type="fixed">
    <origin xyz="-0.00909602748515584 -0.0164020143105288 0.03060219142111" rpy="0 0 0"/>
    <parent link="link4"/>
    <child link="servo_link2"/>
    <axis xyz="0 0 0"/>
  </joint>

  <!-- link5 -->
  <link name="link5">
    <inertial>
      <origin xyz="4.72013959432194E-07 0.00160000918708207 -0.00198445878356862" rpy="0 0 0"/>
      <mass value="0.00101781431105192"/>
      <inertia ixx="2.35870446716609E-08" ixy="5.1941693345402E-15" ixz="-5.55610746904194E-12"
               iyy="2.35867000382259E-08" iyz="-2.48494715503909E-14" izz="4.40385089658091E-08"/>
    </inertial>
    <visual>
      <origin xyz="0 0 0" rpy="0 0 0"/>
      <geometry>
        <mesh filename="${mesh_dir}/link5.STL"/>
      </geometry>
      <material name="">
        <color rgba="0.792156862745098 0.819607843137255 0.933333333333333 1"/>
      </material>
    </visual>
    <collision>
      <origin xyz="0 0 0" rpy="0 0 0"/>
      <geometry>
        <mesh filename="${mesh_dir}/link5.STL"/>
      </geometry>
    </collision>
  </link>

  <!-- joint5 -->
  <joint name="joint5" type="revolute">
    <origin xyz="0.00909545994831443 -0.00159943155199677 0.0240982479335111" rpy="0 0 0"/>
    <parent link="servo_link2"/>
    <child link="link5"/>
    <axis xyz="0 0 0.999999999996305"/>
    <limit lower="-2.09" upper="2.09" effort="1000" velocity="10"/>
  </joint>

  <!-- gripper_link -->
  <link name="gripper_link">
    <inertial>
      <origin xyz="0.013221210110122 -0.000118482264706399 0.0245971620652409" rpy="0 0 0"/>
      <mass value="0.012608908347906"/>
      <inertia ixx="2.46344279226174E-06" ixy="-2.9226509987046E-08" ixz="4.03638406618049E-09"
               iyy="1.25977549723154E-06" iyz="4.23223818388029E-08" izz="1.36545386725773E-06"/>
    </inertial>
    <visual>
      <origin xyz="0 0 0" rpy="0 0 0"/>
      <geometry>
        <mesh filename="${mesh_dir}/gripper_link.STL"/>
      </geometry>
      <material name="">
        <color rgba="0.792156862745098 0.819607843137255 0.933333333333333 1"/>
      </material>
    </visual>
    <collision>
      <origin xyz="0 0 0" rpy="0 0 0"/>
      <geometry>
        <mesh filename="${mesh_dir}/gripper_link.STL"/>
      </geometry>
    </collision>
  </link>

  <!-- gripper_joint -->
  <joint name="gripper_joint" type="fixed">
    <origin xyz="-0.00300062339474341 0.00559999999055451 0.00412090307495294" rpy="0 0 0"/>
    <parent link="link5"/>
    <child link="gripper_link"/>
    <axis xyz="0 0 0"/>
  </joint>



  <!-- camera_connect_link -->
  <link name="camera_connect_link">
    <inertial>
      <origin xyz="0.00883607672288678 0.000868026908448408 4.52285131605501E-05" rpy="0 0 0"/>
      <mass value="0.0163909911496715"/>
      <inertia ixx="8.49090307276901E-06" ixy="6.7869982548383E-09" ixz="8.09018227308212E-10"
               iyy="1.04732160852103E-06" iyz="1.53752630674636E-09" izz="7.84714372132034E-06"/>
    </inertial>
    <visual>
      <origin xyz="0 0 0" rpy="0 0 0"/>
      <geometry>
        <mesh filename="${mesh_dir}/camera_connect_link.STL"/>
      </geometry>
      <material name="">
        <color rgba="0.792156862745098 0.819607843137255 0.933333333333333 1"/>
      </material>
    </visual>
    <collision>
      <origin xyz="0 0 0" rpy="0 0 0"/>
      <geometry>
        <mesh filename="${mesh_dir}/camera_connect_link.STL"/>
      </geometry>
    </collision>
  </link>

  <!-- camera_connect_joint -->
  <joint name="camera_connect_joint" type="fixed">
    <origin xyz="-0.0398070016351449 -0.0178746617915506 0.048387898852254" rpy="-1.5707963267949 -1.57079630572147 1.5707963299424"/>
    <parent link="link4"/>
    <child link="camera_connect_link"/>
    <axis xyz="0 0 0"/>
  </joint>

  <!-- depth_cam_link -->
  <link name="depth_cam">
    <inertial>
      <origin xyz="-0.00969744770499653 -9.72938471235502E-05 -0.00195843932736701" rpy="0 0 0"/>
      <mass value="0.0142258798526639"/>
      <inertia ixx="7.81209323760927E-06" ixy="6.78705210794282E-09" ixz="8.06302150278178E-10"
               iyy="8.6084564322305E-07" iyz="1.69291600809902E-09" izz="7.35336476023221E-06"/>
    </inertial>
    <visual>
      <origin xyz="0 0 0" rpy="0 0 0"/>
      <geometry>
        <mesh filename="${mesh_dir}/depth_cam_link.STL"/>
      </geometry>
      <material name="">
        <color rgba="0.792156862745098 0.819607843137255 0.933333333333333 1"/>
      </material>
    </visual>
    <collision>
      <origin xyz="0 0 0" rpy="0 0 0"/>
      <geometry>
        <mesh filename="${mesh_dir}/depth_cam_link.STL"/>
      </geometry>
    </collision>
  </link>

  <!-- depth_cam_joint -->
  <joint name="depth_cam_joint" type="fixed">
    <origin xyz="0.0200312593027647 0.000989686782880903 0.002650221232401" rpy="0 0 0"/>
    <parent link="camera_connect_link"/>
    <child link="depth_cam"/>
    <axis xyz="0 0 0"/>
  </joint>


</robot>
