<?xml version="1.0" encoding="utf-8"?>
<robot xmlns:xacro="http://www.ros.org/wiki/xacro" name="gripper">
  <!-- 定义 mesh 文件目录 -->
  <xacro:property name="mesh_dir" value="package://mentorpi_description/meshes/gripper" />

  <!-- r_link -->
  <link name="r_link">
    <inertial>
      <origin xyz="0.00149994724977164 -0.00346401105593584 0.00482321845240047" rpy="0 0 0"/>
      <mass value="0.00222253527753655"/>
      <inertia ixx="4.21526138116034E-07" ixy="5.19501864465232E-12" ixz="4.17679673916264E-12"
               iyy="2.26587637141938E-07" iyz="1.34876000686462E-07" izz="1.98272335819046E-07"/>
    </inertial>
    <visual>
      <origin xyz="0 0 0" rpy="0 0 0"/>
      <geometry>
        <mesh filename="${mesh_dir}/r_link.STL"/>
      </geometry>
      <material name="">
        <color rgba="0.792156862745098 0.819607843137255 0.933333333333333 1"/>
      </material>
    </visual>
    <collision>
      <origin xyz="0 0 0" rpy="0 0 0"/>
      <geometry>
        <mesh filename="${mesh_dir}/r_link.STL"/>
      </geometry>
    </collision>
  </link>

  <!-- r_joint -->
  <joint name="r_joint" type="revolute">
    <origin xyz="-0.00309786796953734 -0.0180033588479546 0.026950170065797" rpy="0 0 0"/>
    <parent link="gripper_link"/>
    <child link="r_link"/>
    <axis xyz="0.999999784828379 0.000360574512731351 -0.000548023007084987"/>
    <limit lower="-1.57" upper="1.57" effort="1000" velocity="10"/>
  </joint>

  <!-- r_in_link -->
  <link name="r_in_link">
    <inertial>
      <origin xyz="0.0028002506405902 -0.00669070947646334 0.00894809115952333" rpy="0 0 0"/>
      <mass value="0.000544646546408621"/>
      <inertia ixx="5.37491020930203E-08" ixy="2.39889725373697E-11" ixz="-2.6748069321702E-11"
               iyy="3.39150500148279E-08" iyz="2.5433116150024E-08" izz="2.49447535780213E-08"/>
    </inertial>
    <visual>
      <origin xyz="0 0 0" rpy="0 0 0"/>
      <geometry>
        <mesh filename="${mesh_dir}/r_in_link.STL"/>
      </geometry>
      <material name="">
        <color rgba="0.792156862745098 0.819607843137255 0.933333333333333 1"/>
      </material>
    </visual>
    <collision>
      <origin xyz="0 0 0" rpy="0 0 0"/>
      <geometry>
        <mesh filename="${mesh_dir}/r_in_link.STL"/>
      </geometry>
    </collision>
  </link>

  <!-- r_in_joint -->
  <joint name="r_in_joint" type="revolute">
    <origin xyz="-0.0033016538756948 -0.00934973740913499 0.045358231082756" rpy="0 0 0"/>
    <parent link="gripper_link"/>
    <child link="r_in_link"/>
    <axis xyz="-0.999999999996305 0 0"/>
    <limit lower="-1.57" upper="1.57" effort="1000" velocity="10"/>
    <mimic
      joint="r_joint"
      multiplier="-1"
      offset="0" />
  </joint>

  <!-- r_out_link -->
  <link name="r_out_link">
    <inertial>
      <origin xyz="0.00602749546653089 -0.00204683904280029 0.00321347487104007" rpy="0 0 0"/>
      <mass value="0.00359611173387782"/>
      <inertia ixx="5.3558870244722E-07" ixy="1.02567991710487E-11" ixz="4.42736605831614E-11"
               iyy="4.89191656904075E-07" iyz="-1.12055646828475E-07" izz="6.54412922111908E-08"/>
    </inertial>
    <visual>
      <origin xyz="0 0 0" rpy="0 0 0"/>
      <geometry>
        <mesh filename="${mesh_dir}/r_out_link.STL"/>
      </geometry>
      <material name="">
        <color rgba="0.792156862745098 0.819607843137255 0.933333333333333 1"/>
      </material>
    </visual>
    <collision>
      <origin xyz="0 0 0" rpy="0 0 0"/>
      <geometry>
        <mesh filename="${mesh_dir}/r_out_link.STL"/>
      </geometry>
    </collision>
  </link>

  <!-- r_out_joint -->
  <joint name="r_out_joint" type="revolute">
    <origin xyz="0.000243406210538505 -0.0189415012666699 0.0235398453193471" rpy="0 0 0"/>
    <parent link="r_in_link"/>
    <child link="r_out_link"/>
    <axis xyz="0.999999999996305 0 0"/>
    <limit lower="-1.57" upper="1.57" effort="1000" velocity="10"/>
    <mimic
      joint="r_joint"
      multiplier="-1"
      offset="0" />
  </joint>

  <!-- l_link -->
  <link name="l_link">
    <inertial>
      <origin xyz="-4.64599890241113E-05 0.00398305310950446 0.00598800031528041" rpy="0 0 0"/>
      <mass value="0.0020746166929888"/>
      <inertia ixx="4.11015560961754E-07" ixy="-5.25238965230942E-12" ixz="2.45954657756359E-12"
               iyy="2.18469388572317E-07" iyz="-1.29532803401027E-07" izz="1.95658095118032E-07"/>
    </inertial>
    <visual>
      <origin xyz="0 0 0" rpy="0 0 0"/>
      <geometry>
        <mesh filename="${mesh_dir}/l_link.STL"/>
      </geometry>
      <material name="">
        <color rgba="0.792156862745098 0.819607843137255 0.933333333333333 1"/>
      </material>
    </visual>
    <collision>
      <origin xyz="0 0 0" rpy="0 0 0"/>
      <geometry>
        <mesh filename="${mesh_dir}/l_link.STL"/>
      </geometry>
    </collision>
  </link>

  <!-- l_joint -->
  <joint name="l_joint" type="revolute">
    <origin xyz="-0.0015514745324403 0.00972619580013072 0.026264953269009" rpy="0 0 0"/>
    <parent link="gripper_link"/>
    <child link="l_link"/>
    <axis xyz="-0.999999999996305 0 0"/>
    <limit lower="-1.57" upper="1.57" effort="1000" velocity="10"/>
    <mimic
      joint="r_joint"
      multiplier="1"
      offset="0" />
  </joint>

  <!-- l_in_link -->
  <link name="l_in_link">
    <inertial>
      <origin xyz="0.00257791688948808 0.00704230178358273 0.00837714360447922" rpy="0 0 0"/>
      <mass value="0.000544639843975015"/>
      <inertia ixx="5.37483996548162E-08" ixy="-2.39534129541767E-11" ixz="-2.67505714875717E-11"
               iyy="3.39145613158354E-08" iyz="-2.54330100463506E-08" izz="2.49443208621476E-08"/>
    </inertial>
    <visual>
      <origin xyz="0 0 0" rpy="0 0 0"/>
      <geometry>
        <mesh filename="${mesh_dir}/l_in_link.STL"/>
      </geometry>
      <material name="">
        <color rgba="0.792156862745098 0.819607843137255 0.933333333333333 1"/>
      </material>
    </visual>
    <collision>
      <origin xyz="0 0 0" rpy="0 0 0"/>
      <geometry>
        <mesh filename="${mesh_dir}/l_in_link.STL"/>
      </geometry>
    </collision>
  </link>

  <!-- l_in_joint -->
  <joint name="l_in_joint" type="revolute">
    <origin xyz="-0.00307929229401988 0.000993411611255865 0.045929296528685" rpy="0 0 0"/>
    <parent link="gripper_link"/>
    <child link="l_in_link"/>
    <axis xyz="-0.999999999996305 0 0"/>
    <limit lower="-1.57" upper="1.57" effort="1000" velocity="10"/>
    <mimic
      joint="r_joint"
      multiplier="1"
      offset="0" />
  </joint>

  <!-- l_out_link -->
  <link name="l_out_link">
    <inertial>
      <origin xyz="0.00602751098730102 0.00205406252590601 0.00323675138812862" rpy="0 0 0"/>
      <mass value="0.00359610151131339"/>
      <inertia ixx="5.35588519730572E-07" ixy="-1.03817512457255E-11" ixz="4.4434863396461E-11"
               iyy="4.89157912609529E-07" iyz="1.12117658350424E-07" izz="6.54743895995382E-08"/>
    </inertial>
    <visual>
      <origin xyz="0 0 0" rpy="0 0 0"/>
      <geometry>
        <mesh filename="${mesh_dir}/l_out_link.STL"/>
      </geometry>
      <material name="">
        <color rgba="0.792156862745098 0.819607843137255 0.933333333333333 1"/>
      </material>
    </visual>
    <collision>
      <origin xyz="0 0 0" rpy="0 0 0"/>
      <geometry>
        <mesh filename="${mesh_dir}/l_out_link.STL"/>
      </geometry>
    </collision>
  </link>

  <!-- l_out_joint -->
  <joint name="l_out_joint" type="revolute">
    <origin xyz="2.1044529118136E-05 0.0192824862431322 0.022949235908343" rpy="0 0 0"/>
    <parent link="l_in_link"/>
    <child link="l_out_link"/>
    <axis xyz="-0.999999999996305 0 0"/>
    <limit lower="-1.57" upper="1.57" effort="1000" velocity="10"/>
    <mimic
      joint="r_joint"
      multiplier="-1"
      offset="0" />
  </joint>
  
</robot>
